Workbook

Sheet README
A1: MENVA marketing tracker
A3: Yellow cells are for you to fill in. White cells are filled already or calculated: do not type over formulas.
A4: Rows in grey italics are EXAMPLES that show the format. Delete them when you start.
A6: Tabs
A7: Weekly KPIs: every Monday, copy the week's numbers from Instagram Insights and your DMs/WhatsApp. Rates calculate themselves.
A8: Content log: all 72 calendar posts with their dates (default start 5 Oct 2026). About 7 days after each post, enter reach, likes, comments, sends, saves.
A9: Pillar summary: which kind of post works best, calculated from the Content log. Every 4 weeks, make more of the top pillars.
A10: CRM: every restaurant you contact (columns from social/marketing/sales-kit.md section 8). Status and channel are dropdowns; counts on the right.
A11: Influencers: creators you invite (verify follower counts first, see research/influencers.md).
A12: Campaigns: the 6 campaigns in social/marketing/campaigns.md, with their KPI; write the kill criterion from that file.
A14: Where the numbers come from
A15: Instagram app > Professional dashboard > Insights (reach, shares = "sends", saves, profile visits). Pilot numbers: the private /stats page.
... A17: If the calendar starts on another date, change Content log B2 and Weekly KPIs A2; the other dates follow.

Sheet Weekly KPIs
A1: Week starting | B1: Followers (end of week) | C1: New followers | D1: Accounts reached | E1: Sends (shares) | F1: Saves | G1: Profile visits | H1: Link taps | I1: "PILOT" DMs | J1: "PILOT" WhatsApps | K1: Demos booked | L1: Pilots signed | M1: Sends per 1k reach | N1: Saves per 1k reach | O1: Leads (DM + WhatsApp) | P1: Lead to demo rate | Q1: Notes
A2: 46300 | M2: =IF(N(D2)=0,"",E2/D2*1000) | N2: =IF(N(D2)=0,"",F2/D2*1000) | O2: =IF(AND(I2="",J2=""),"",N(I2)+N(J2)) | P2: =IF(N(O2)=0,"",K2/O2)
A3: =A2+7 | C3: =IF(OR(B3="",B2=""),"",B3-B2) | M3: =IF(N(D3)=0,"",E3/D3*1000) | N3: =IF(N(D3)=0,"",F3/D3*1000) | O3: =IF(AND(I3="",J3=""),"",N(I3)+N(J3)) | P3: =IF(N(O3)=0,"",K3/O3)
A4: =A3+7 | C4: =IF(OR(B4="",B3=""),"",B4-B3) | M4: =IF(N(D4)=0,"",E4/D4*1000) | N4: =IF(N(D4)=0,"",F4/D4*1000) | O4: =IF(AND(I4="",J4=""),"",N(I4)+N(J4)) | P4: =IF(N(O4)=0,"",K4/O4)
A5: =A4+7 | C5: =IF(OR(B5="",B4=""),"",B5-B4) | M5: =IF(N(D5)=0,"",E5/D5*1000) | N5: =IF(N(D5)=0,"",F5/D5*1000) | O5: =IF(AND(I5="",J5=""),"",N(I5)+N(J5)) | P5: =IF(N(O5)=0,"",K5/O5)
A6: =A5+7 | C6: =IF(OR(B6="",B5=""),"",B6-B5) | M6: =IF(N(D6)=0,"",E6/D6*1000) | N6: =IF(N(D6)=0,"",F6/D6*1000) | O6: =IF(AND(I6="",J6=""),"",N(I6)+N(J6)) | P6: =IF(N(O6)=0,"",K6/O6)
A7: =A6+7 | C7: =IF(OR(B7="",B6=""),"",B7-B6) | M7: =IF(N(D7)=0,"",E7/D7*1000) | N7: =IF(N(D7)=0,"",F7/D7*1000) | O7: =IF(AND(I7="",J7=""),"",N(I7)+N(J7)) | P7: =IF(N(O7)=0,"",K7/O7)
A8: =A7+7 | C8: =IF(OR(B8="",B7=""),"",B8-B7) | M8: =IF(N(D8)=0,"",E8/D8*1000) | N8: =IF(N(D8)=0,"",F8/D8*1000) | O8: =IF(AND(I8="",J8=""),"",N(I8)+N(J8)) | P8: =IF(N(O8)=0,"",K8/O8)
A9: =A8+7 | C9: =IF(OR(B9="",B8=""),"",B9-B8) | M9: =IF(N(D9)=0,"",E9/D9*1000) | N9: =IF(N(D9)=0,"",F9/D9*1000) | O9: =IF(AND(I9="",J9=""),"",N(I9)+N(J9)) | P9: =IF(N(O9)=0,"",K9/O9)
A10: =A9+7 | C10: =IF(OR(B10="",B9=""),"",B10-B9) | M10: =IF(N(D10)=0,"",E10/D10*1000) | N10: =IF(N(D10)=0,"",F10/D10*1000) | O10: =IF(AND(I10="",J10=""),"",N(I10)+N(J10)) | P10: =IF(N(O10)=0,"",K10/O10)
A11: =A10+7 | C11: =IF(OR(B11="",B10=""),"",B11-B10) | M11: =IF(N(D11)=0,"",E11/D11*1000) | N11: =IF(N(D11)=0,"",F11/D11*1000) | O11: =IF(AND(I11="",J11=""),"",N(I11)+N(J11)) | P11: =IF(N(O11)=0,"",K11/O11)
A12: =A11+7 | C12: =IF(OR(B12="",B11=""),"",B12-B11) | M12: =IF(N(D12)=0,"",E12/D12*1000) | N12: =IF(N(D12)=0,"",F12/D12*1000) | O12: =IF(AND(I12="",J12=""),"",N(I12)+N(J12)) | P12: =IF(N(O12)=0,"",K12/O12)
A13: =A12+7 | C13: =IF(OR(B13="",B12=""),"",B13-B12) | M13: =IF(N(D13)=0,"",E13/D13*1000) | N13: =IF(N(D13)=0,"",F13/D13*1000) | O13: =IF(AND(I13="",J13=""),"",N(I13)+N(J13)) | P13: =IF(N(O13)=0,"",K13/O13)
A14: =A13+7 | C14: =IF(OR(B14="",B13=""),"",B14-B13) | M14: =IF(N(D14)=0,"",E14/D14*1000) | N14: =IF(N(D14)=0,"",F14/D14*1000) | O14: =IF(AND(I14="",J14=""),"",N(I14)+N(J14)) | P14: =IF(N(O14)=0,"",K14/O14)
... A21: =A20+7 | C21: =IF(OR(B21="",B20=""),"",B21-B20) | M21: =IF(N(D21)=0,"",E21/D21*1000) | N21: =IF(N(D21)=0,"",F21/D21*1000) | O21: =IF(AND(I21="",J21=""),"",N(I21)+N(J21)) | P21: =IF(N(O21)=0,"",K21/O21)

Sheet Content log
A1: # | B1: Date | C1: Day | D1: Post id | E1: Pillar | F1: Audience | G1: Format | H1: Headline (slide 1) | I1: Reach | J1: Likes | K1: Comments | L1: Sends (shares) | M1: Saves | N1: Sends per 1k reach | O1: Saves per 1k reach | P1: Notes / what to repeat
A2: 1 | B2: 46300 | C2: =TEXT(B2,"ddd") | D2: hello-lahore | E2: see-it-first | F2: diners | G2: carousel | H2: See it before you order it. | N2: =IF(N(I2)=0,"",L2/I2*1000) | O2: =IF(N(I2)=0,"",M2/I2*1000)
A3: 2 | B3: =$B$2+1 | C3: =TEXT(B3,"ddd") | D3: waiter-is-back | E3: relatable | F3: diners | G3: single | H3: The waiter is back. Again. | N3: =IF(N(I3)=0,"",L3/I3*1000) | O3: =IF(N(I3)=0,"",M3/I3*1000)
A4: 3 | B4: =$B$2+3 | C4: =TEXT(B4,"ddd") | D4: scan-not-photo | E4: see-it-first | F4: diners | G4: single | H4: This is a scan, not a photo. | N4: =IF(N(I4)=0,"",L4/I4*1000) | O4: =IF(N(I4)=0,"",M4/I4*1000)
A5: 4 | B5: =$B$2+4 | C5: =TEXT(B5,"ddd") | D5: friday-pick-one | E5: relatable | F5: diners | G5: single | H5: Friday night. Pick one. | N5: =IF(N(I5)=0,"",L5/I5*1000) | O5: =IF(N(I5)=0,"",M5/I5*1000)
A6: 5 | B6: =$B$2+5 | C6: =TEXT(B6,"ddd") | D6: group-order-guide | E6: menu-truth | F6: diners | G6: carousel | H6: Ordering for eight, without the chaos. | N6: =IF(N(I6)=0,"",L6/I6*1000) | O6: =IF(N(I6)=0,"",M6/I6*1000)
A7: 6 | B7: =$B$2+6 | C7: =TEXT(B7,"ddd") | D7: quietest-salesperson | E7: for-restaurants | F7: restaurants | G7: carousel | H7: Your menu is your quietest salesperson. | N7: =IF(N(I7)=0,"",L7/I7*1000) | O7: =IF(N(I7)=0,"",M7/I7*1000)
A8: 7 | B8: =$B$2+8 | C8: =TEXT(B8,"ddd") | D8: menu-photo-vs-plate | E8: menu-truth | F8: diners | G8: single | H8: Menu photos lie. Scans don't. | N8: =IF(N(I8)=0,"",L8/I8*1000) | O8: =IF(N(I8)=0,"",M8/I8*1000)
A9: 8 | B9: =$B$2+10 | C9: =TEXT(B9,"ddd") | D9: how-it-works-3-steps | E9: see-it-first | F9: diners | G9: carousel | H9: Scan the code on your table | N9: =IF(N(I9)=0,"",L9/I9*1000) | O9: =IF(N(I9)=0,"",M9/I9*1000)
A10: 9 | B10: =$B$2+11 | C10: =TEXT(B10,"ddd") | D10: world-food-day | E10: relatable | F10: diners | G10: single | H10: Order what you actually want. | N10: =IF(N(I10)=0,"",L10/I10*1000) | O10: =IF(N(I10)=0,"",M10/I10*1000)
A11: 10 | B11: =$B$2+12 | C11: =TEXT(B11,"ddd") | D11: pov-portion-size | E11: relatable | F11: diners | G11: single | H11: You didn't check the portion size. | N11: =IF(N(I11)=0,"",L11/I11*1000) | O11: =IF(N(I11)=0,"",M11/I11*1000)
A12: 11 | B12: =$B$2+13 | C12: =TEXT(B12,"ddd") | D12: faq-do-i-need-an-app | E12: see-it-first | F12: diners | G12: carousel | H12: Do I need an app? | N12: =IF(N(I12)=0,"",L12/I12*1000) | O12: =IF(N(I12)=0,"",M12/I12*1000)
A13: 12 | B13: =$B$2+15 | C13: =TEXT(B13,"ddd") | D13: the-safe-order | E13: relatable | F13: diners | G13: single | H13: New restaurant. New menu. Same order. | N13: =IF(N(I13)=0,"",L13/I13*1000) | O13: =IF(N(I13)=0,"",M13/I13*1000)
A14: 13 | B14: =$B$2+17 | C14: =TEXT(B14,"ddd") | D14: turn-it-around | E14: see-it-first | F14: diners | G14: single | H14: Turn it around. | N14: =IF(N(I14)=0,"",L14/I14*1000) | O14: =IF(N(I14)=0,"",M14/I14*1000)
A15: 14 | B15: =$B$2+18 | C15: =TEXT(B15,"ddd") | D15: owners-what-guests-ask | E15: for-restaurants | F15: restaurants | G15: single | H15: The most asked question in your restaurant: "What does it look like?" | N15: =IF(N(I15)=0,"",L15/I15*1000) | O15: =IF(N(I15)=0,"",M15/I15*1000)
A16: 15 | B16: =$B$2+19 | C16: =TEXT(B16,"ddd") | D16: weekend-plans | E16: relatable | F16: diners | G16: single | H16: Weekend plans, sorted. | N16: =IF(N(I16)=0,"",L16/I16*1000) | O16: =IF(N(I16)=0,"",M16/I16*1000)
A17: 16 | B17: =$B$2+20 | C17: =TEXT(B17,"ddd") | D17: three-things-a-scan-shows | E17: menu-truth | F17: diners | G17: carousel | H17: Three things a menu line never tells you. | N17: =IF(N(I17)=0,"",L17/I17*1000) | O17: =IF(N(I17)=0,"",M17/I17*1000)
A18: 17 | B18: =$B$2+22 | C18: =TEXT(B18,"ddd") | D18: menu-anxiety | E18: relatable | F18: diners | G18: single | H18: Twelve pages. No pictures. The waiter is watching. | N18: =IF(N(I18)=0,"",L18/I18*1000) | O18: =IF(N(I18)=0,"",M18/I18*1000)
A19: 18 | B19: =$B$2+24 | C19: =TEXT(B19,"ddd") | D19: owners-plating-credit | E19: for-restaurants | F19: restaurants | G19: single | H19: Your plating, before the order. | N19: =IF(N(I19)=0,"",L19/I19*1000) | O19: =IF(N(I19)=0,"",M19/I19*1000)
A20: 19 | B20: =$B$2+25 | C20: =TEXT(B20,"ddd") | D20: pick-one-sandwich-board | E20: relatable | F20: diners | G20: single | H20: Lunch or dinner, pick one. | N20: =IF(N(I20)=0,"",L20/I20*1000) | O20: =IF(N(I20)=0,"",M20/I20*1000)
A21: 20 | B21: =$B$2+26 | C21: =TEXT(B21,"ddd") | D21: halloween-scary-menus | E21: relatable | F21: diners | G21: carousel | H21: The scariest thing in Lahore tonight is a menu with no photos. | N21: =IF(N(I21)=0,"",L21/I21*1000) | O21: =IF(N(I21)=0,"",M21/I21*1000)
A22: 21 | B22: =$B$2+27 | C22: =TEXT(B22,"ddd") | D22: save-for-date-night | E22: see-it-first | F22: diners | G22: single | H22: Date night. No surprises. | N22: =IF(N(I22)=0,"",L22/I22*1000) | O22: =IF(N(I22)=0,"",M22/I22*1000)
A23: 22 | B23: =$B$2+29 | C23: =TEXT(B23,"ddd") | D23: smog-season-indoors | E23: relatable | F23: diners | G23: single | H23: Smog outside. Good food inside. | N23: =IF(N(I23)=0,"",L23/I23*1000) | O23: =IF(N(I23)=0,"",M23/I23*1000)
A24: 23 | B24: =$B$2+31 | C24: =TEXT(B24,"ddd") | D24: how-we-scan | E24: behind-the-scan | F24: both | G24: carousel | H24: How a dish becomes a scan. | N24: =IF(N(I24)=0,"",L24/I24*1000) | O24: =IF(N(I24)=0,"",M24/I24*1000)
A25: 24 | B25: =$B$2+32 | C25: =TEXT(B25,"ddd") | D25: true-size | E25: see-it-first | F25: diners | G25: single | H25: No zoom. No tricks. True size. | N25: =IF(N(I25)=0,"",L25/I25*1000) | O25: =IF(N(I25)=0,"",M25/I25*1000)
A26: 25 | B26: =$B$2+33 | C26: =TEXT(B26,"ddd") | D26: sight-test-1 | E26: menu-truth | F26: diners | G26: carousel | H26: Taste tests happen after you order. Sight tests happen before. | N26: =IF(N(I26)=0,"",L26/I26*1000) | O26: =IF(N(I26)=0,"",M26/I26*1000)
A27: 26 | B27: =$B$2+34 | C27: =TEXT(B27,"ddd") | D27: owners-faq-1 | E27: for-restaurants | F27: restaurants | G27: carousel | H27: Do guests need an app? | N27: =IF(N(I27)=0,"",L27/I27*1000) | O27: =IF(N(I27)=0,"",M27/I27*1000)
A28: 27 | B28: =$B$2+36 | C28: =TEXT(B28,"ddd") | D28: you-vs-menu | E28: menu-truth | F28: diners | G28: single | H28: Which one makes you hungry? | N28: =IF(N(I28)=0,"",L28/I28*1000) | O28: =IF(N(I28)=0,"",M28/I28*1000)
A29: 28 | B29: =$B$2+38 | C29: =TEXT(B29,"ddd") | D29: show-the-waiter | E29: see-it-first | F29: diners | G29: single | H29: Build your list. Show the waiter. | N29: =IF(N(I29)=0,"",L29/I29*1000) | O29: =IF(N(I29)=0,"",M29/I29*1000)
A30: 29 | B30: =$B$2+39 | C30: =TEXT(B30,"ddd") | D30: the-overorderer | E30: relatable | F30: diners | G30: single | H30: The over-orderer. | N30: =IF(N(I30)=0,"",L30/I30*1000) | O30: =IF(N(I30)=0,"",M30/I30*1000)
A31: 30 | B31: =$B$2+40 | C31: =TEXT(B31,"ddd") | D31: closeup-steak | E31: see-it-first | F31: diners | G31: single | H31: Close enough to count the grill marks. | N31: =IF(N(I31)=0,"",L31/I31*1000) | O31: =IF(N(I31)=0,"",M31/I31*1000)
A32: 31 | B32: =$B$2+41 | C32: =TEXT(B32,"ddd") | D32: owners-problem-list | E32: for-restaurants | F32: restaurants | G32: single | H32: Five signs your menu is costing you orders | N32: =IF(N(I32)=0,"",L32/I32*1000) | O32: =IF(N(I32)=0,"",M32/I32*1000)
A33: 32 | B33: =$B$2+43 | C33: =TEXT(B33,"ddd") | D33: the-photographer | E33: relatable | F33: diners | G33: single | H33: The photographer. Camera eats first. | N33: =IF(N(I33)=0,"",L33/I33*1000) | O33: =IF(N(I33)=0,"",M33/I33*1000)
A34: 33 | B34: =$B$2+45 | C34: =TEXT(B34,"ddd") | D34: no-ai-food | E34: behind-the-scan | F34: both | G34: single | H34: No AI food. Ever. | N34: =IF(N(I34)=0,"",L34/I34*1000) | O34: =IF(N(I34)=0,"",M34/I34*1000)
A35: 34 | B35: =$B$2+46 | C35: =TEXT(B35,"ddd") | D35: is-it-worth-the-hype | E35: relatable | F35: diners | G35: single | H35: "Is it worth the hype?" Decide before you order. | N35: =IF(N(I35)=0,"",L35/I35*1000) | O35: =IF(N(I35)=0,"",M35/I35*1000)
A36: 35 | B36: =$B$2+47 | C36: =TEXT(B36,"ddd") | D36: what-changes-for-guests | E36: see-it-first | F36: diners | G36: carousel | H36: What changes when you see it first. | N36: =IF(N(I36)=0,"",L36/I36*1000) | O36: =IF(N(I36)=0,"",M36/I36*1000)
A37: 36 | B37: =$B$2+48 | C37: =TEXT(B37,"ddd") | D37: owners-how-pilot-works | E37: for-restaurants | F37: restaurants | G37: carousel | H37: How the pilot works. | N37: =IF(N(I37)=0,"",L37/I37*1000) | O37: =IF(N(I37)=0,"",M37/I37*1000)
A38: 37 | B38: =$B$2+50 | C38: =TEXT(B38,"ddd") | D38: wedding-season | E38: relatable | F38: diners | G38: single | H38: Shaadi ka khana fix hai. | N38: =IF(N(I38)=0,"",L38/I38*1000) | O38: =IF(N(I38)=0,"",M38/I38*1000)
A39: 38 | B39: =$B$2+52 | C39: =TEXT(B39,"ddd") | D39: the-sharer | E39: relatable | F39: diners | G39: single | H39: Three pieces. Six people. | N39: =IF(N(I39)=0,"",L39/I39*1000) | O39: =IF(N(I39)=0,"",M39/I39*1000)
A40: 39 | B40: =$B$2+53 | C40: =TEXT(B40,"ddd") | D40: white-friday | E40: relatable | F40: diners | G40: single | H40: Best deal today: no surprises. | N40: =IF(N(I40)=0,"",L40/I40*1000) | O40: =IF(N(I40)=0,"",M40/I40*1000)
...

Sheet Pillar summary
A1: Pillar | B1: Posts planned | C1: Posts with data | D1: Avg sends per 1k reach | E1: Avg saves per 1k reach | F1: Total "PILOT" leads (from Weekly KPIs)
A2: behind-the-scan | B2: =COUNTIF('Content log'!$E$2:$E$73,A2) | C2: =COUNTIFS('Content log'!$E$2:$E$73,A2,'Content log'!$I$2:$I$73,">0") | D2: =IF(C2=0,"",AVERAGEIFS('Content log'!$N$2:$N$73,'Content log'!$E$2:$E$73,A2,'Content log'!$I$2:$I$73,">0")) | E2: =IF(C2=0,"",AVERAGEIFS('Content log'!$O$2:$O$73,'Content log'!$E$2:$E$73,A2,'Content log'!$I$2:$I$73,">0"))
A3: for-restaurants | B3: =COUNTIF('Content log'!$E$2:$E$73,A3) | C3: =COUNTIFS('Content log'!$E$2:$E$73,A3,'Content log'!$I$2:$I$73,">0") | D3: =IF(C3=0,"",AVERAGEIFS('Content log'!$N$2:$N$73,'Content log'!$E$2:$E$73,A3,'Content log'!$I$2:$I$73,">0")) | E3: =IF(C3=0,"",AVERAGEIFS('Content log'!$O$2:$O$73,'Content log'!$E$2:$E$73,A3,'Content log'!$I$2:$I$73,">0"))
A4: menu-truth | B4: =COUNTIF('Content log'!$E$2:$E$73,A4) | C4: =COUNTIFS('Content log'!$E$2:$E$73,A4,'Content log'!$I$2:$I$73,">0") | D4: =IF(C4=0,"",AVERAGEIFS('Content log'!$N$2:$N$73,'Content log'!$E$2:$E$73,A4,'Content log'!$I$2:$I$73,">0")) | E4: =IF(C4=0,"",AVERAGEIFS('Content log'!$O$2:$O$73,'Content log'!$E$2:$E$73,A4,'Content log'!$I$2:$I$73,">0"))
A5: relatable | B5: =COUNTIF('Content log'!$E$2:$E$73,A5) | C5: =COUNTIFS('Content log'!$E$2:$E$73,A5,'Content log'!$I$2:$I$73,">0") | D5: =IF(C5=0,"",AVERAGEIFS('Content log'!$N$2:$N$73,'Content log'!$E$2:$E$73,A5,'Content log'!$I$2:$I$73,">0")) | E5: =IF(C5=0,"",AVERAGEIFS('Content log'!$O$2:$O$73,'Content log'!$E$2:$E$73,A5,'Content log'!$I$2:$I$73,">0"))
A6: see-it-first | B6: =COUNTIF('Content log'!$E$2:$E$73,A6) | C6: =COUNTIFS('Content log'!$E$2:$E$73,A6,'Content log'!$I$2:$I$73,">0") | D6: =IF(C6=0,"",AVERAGEIFS('Content log'!$N$2:$N$73,'Content log'!$E$2:$E$73,A6,'Content log'!$I$2:$I$73,">0")) | E6: =IF(C6=0,"",AVERAGEIFS('Content log'!$O$2:$O$73,'Content log'!$E$2:$E$73,A6,'Content log'!$I$2:$I$73,">0"))
A7: All | B7: =SUM(B2:B6) | C7: =SUM(C2:C6) | F7: =SUM('Weekly KPIs'!O2:O21)

Sheet CRM
A1: Restaurant name | B1: Area | C1: Category | D1: Contact name | E1: Role | F1: Phone whatsapp | G1: Instagram handle | H1: Email | I1: First contact date | J1: First contact channel | K1: Last contact date | L1: Status | M1: Objection raised | N1: Demo date | O1: Demo outcome notes | P1: Pilot start date | Q1: Referred by | R1: Next action | S1: Next action date | U1: Status | V1: Count
A2: EXAMPLE: Café Name | B2: Gulberg | C2: Café / desserts | D2: Owner name | E2: Owner | F2: 03xx xxxxxxx | G2: @cafe | I2: 46302 | J2: Walk-in | K2: 46304 | L2: Demo booked | M2: "Guests don't use QR" | N2: 46309 | R2: Demo at 4 pm, bring the one-pager | S2: 46309 | U2: To contact | V2: =COUNTIF($L$3:$L$201,U2)
A3: RARE Steakhouse | B3: MM Alam Rd, Gulberg (rooftop, Gulberg Galleria) | C3: Steakhouse / premium grill | L3: To contact | O3: Wagyu-focused steakhouse per source; premium cuts are exactly the 'how big is the cut' moment AR answers. | R3: Verify it still fits (priority A), then first contact | U3: Contacted | V3: =COUNTIF($L$3:$L$201,U3)
A4: Cafe Zouk | B4: MM Alam Rd, Gulberg | C4: Fine dining / steakhouse | L4: To contact | O4: Sits in both the steakhouse and fine-dining source lists (ribeye/fillet/lamb steaks, Continental-Pan Asian-seafood menu) — dramatic plates, established brand. | R4: Verify it still fits (priority A), then first contact | U4: Replied | V4: =COUNTIF($L$3:$L$201,U4)
A5: Salt'n Pepper | B5: MM Alam Rd, Gulberg (flagship) | C5: Steakhouse / premium grill | L5: To contact | O5: Long-standing charcoal-grill brand on MM Alam Rd — established following, visually strong grilled plates. | R5: Verify it still fits (priority A), then first contact | U5: Demo booked | V5: =COUNTIF($L$3:$L$201,U5)
A6: Gaia | C6: Fine dining / Pan-Asian | L6: To contact | O6: Described as premium Pan-Asian with theatrical teppanyaki grills and dark, moody luxury interior — a hero-dish moment AR can extend to the table. | R6: Verify it still fits (priority A), then first contact | U6: Demo done | V6: =COUNTIF($L$3:$L$201,U6)
A7: The Skye | B7: Gulberg III (18th floor, Indigo Hotel) | C7: Fine dining / rooftop | L7: To contact | O7: Billed as Lahore's highest rooftop dining destination with 360-degree skyline views — premium experience spend, owner likely to see AR as the same category. | R7: Verify it still fits (priority A), then first contact | U7: Pilot signed | V7: =COUNTIF($L$3:$L$201,U7)
A8: El Momento Steakhouse | B8: MM Alam Rd, Gulberg 2 | C8: Steakhouse / premium grill | L8: To contact | O8: Tops multiple 2026 steakhouse rankings; imported aged beef cuts, sophisticated ambiance — same category as the pilot dish (steak board). | R8: Verify it still fits (priority A), then first contact | U8: Paid | V8: =COUNTIF($L$3:$L$201,U8)
A9: Cafe Aylanto | B9: MM Alam Rd | C9: Fine dining / Mediterranean | L9: To contact | O9: Long-running benchmark for upscale Mediterranean dining in Lahore — brand-conscious owner likely to value a tasteful AR menu over a gimmick. | R9: Verify it still fits (priority A), then first contact | U9: Not now | V9: =COUNTIF($L$3:$L$201,U9)
A10: Sikomoro | C10: Fine dining / new opening | L10: To contact | O10: New poolside dining spot with French/Italian/continental plates and an in-house bakery — pre-launch or early menu means no legacy PDF to fight. | R10: Verify it still fits (priority A), then first contact | U10: Dormant | V10: =COUNTIF($L$3:$L$201,U10)
A11: Olive Fork | B11: Bahria Town Lahore (opposite Grand Masjid) | C11: New opening | L11: To contact | O11: Recently opened per source — early-days restaurants are the easiest 'yes' before their menu is printed. | R11: Verify it still fits (priority A), then first contact
A12: Andaaz | B12: Fort Road, near Badshahi Mosque | C12: Fine dining / heritage rooftop | L12: To contact | O12: Rooftop Pakistani fine dining combining heritage setting with plated food — visually strong, tourist and status-dining crowd. | R12: Verify it still fits (priority A), then first contact
A13: Arizona Grill | B13: Bahria Town | C13: Steakhouse / grill | L13: To contact | O13: Steaks, burgers and grilled sandwiches in a newer commercial area with less marketing-tech saturation, per sales-kit area logic. | R13: Verify it still fits (priority A), then first contact
A14: Spice Bazaar | C14: Fine dining / Pakistani | L14: To contact | O14: Established Pakistani fine-dining name (has its own Wikipedia page) — status-dining crowd, plated hero dishes. | R14: Verify it still fits (priority A), then first contact
A15: Bangkok Steakhouse | B15: Gulberg | C15: Steakhouse / premium grill | L15: To contact | O15: Local favourite for generous grilled portions and marinades — the portion-size question AR is built to answer. | R15: Verify it still fits (priority A), then first contact
A16: Xander's | B16: MM Alam Rd, Gulberg | C16: Steakhouse / premium casual grill | L16: To contact | O16: Casual-upscale steaks and grilled meats on MM Alam Rd — fits premium casual grill category directly. | R16: Verify it still fits (priority A), then first contact
A17: Promenade | C17: Photogenic cafe / new opening | L17: To contact | O17: Reported as Pakistan's first Bridgerton-themed cafe in Lahore — high novelty and photo appeal, natural fit for an AR menu as a launch story. | R17: Verify it still fits (priority A), then first contact
A18: Mystique Restaurant | C18: Fine dining | L18: To contact | O18: Self-described upscale spot blending continental, Asian and Pakistani dishes, positioned for corporate dinners and special occasions — experience-spend owner. | R18: Verify it still fits (priority A), then first contact
A19: Dahlia Nursery + Cafe | C19: Photogenic cafe | L19: To contact | O19: Plant-filled nursery-cafe aesthetic — guests already photograph the space; natural extension to photograph/AR the dish too. | R19: Verify it still fits (priority B), then first contact
A20: Cafe Forest 14 | C20: Photogenic cafe | L20: To contact | O20: "Bali in Lahore" indoor-forest theme built for sunset photography — strong Instagram-first crowd. | R20: Verify it still fits (priority B), then first contact
A21: Bistro Noir | C21: Photogenic cafe | L21: To contact | O21: Monochrome, minimalist-luxury styling described as a deliberate design statement — brand-conscious owner. | R21: Verify it still fits (priority B), then first contact
A22: Yanu | C22: Photogenic cafe / poolside | L22: To contact | O22: Described as a Pinterest-style poolside spot for brunch and evening photoshoots — guests are already in a photograph-the-food mindset. | R22: Verify it still fits (priority B), then first contact
A23: Meet Me In Paris | C23: Photogenic cafe | L23: To contact | O23: Floral facade described as one of the most photographed cafe entrances in Lahore — proof guests already stop to photograph before they order. | R23: Verify it still fits (priority B), then first contact
A24: COMO Museum of Art Cafe | C24: Photogenic cafe / gallery | L24: To contact | O24: Cafe inside an art museum, modern architecture — audience already primed for a considered visual experience. | R24: Verify it still fits (priority B), then first contact
A25: Deja by Khadija | C25: Photogenic dessert cafe | L25: To contact | O25: Pink-and-white dessert cafe described as "every corner is picture-perfect" — decorated cakes are a hero-dish candidate. | R25: Verify it still fits (priority B), then first contact
A26: Sweet Affairs | B26: Gulberg + DHA | C26: Photogenic cafe / dessert | L26: To contact | O26: Whimsical, pastel decor since 2011; skillet-cookie dessert is a shareable, photogenic hero item. | R26: Verify it still fits (priority B), then first contact
A27: The Urban Eatery | B27: DHA | C27: Photogenic cafe / casual dining | L27: To contact | O27: Listed among Lahore's aesthetic hangout spots — established Instagram-forward brunch crowd. | R27: Verify it still fits (priority B), then first contact
A28: English Tea House | B28: Gulberg + DHA | C28: Photogenic cafe / breakfast | L28: To contact | O28: Listed among Lahore's aesthetic hangout spots for breakfast — photogenic plating, brunch crowd. | R28: Verify it still fits (priority B), then first contact
A29: Sweet Tooth | B29: Mall 1 | C29: Dessert cafe | L29: To contact | O29: Described as one of the newest Instagrammable dessert spots in town, with wall art and a cozy setting built for photos. | R29: Verify it still fits (priority B), then first contact
A30: Layers - Bakeshop | C30: Dessert / bakery | L30: To contact | O30: Affordable cupcakes, cakes and sundaes (Galaxy Sundae, salted caramel cake called out by name) — visual, shareable desserts. | R30: Verify it still fits (priority B), then first contact
A31: Dessert Directory | C31: Dessert / boutique bakery | L31: To contact | O31: French-inspired boutique dessert shop aggregating home-based bakers — novelty, photogenic packaging. | R31: Verify it still fits (priority B), then first contact
A32: Freddy's Cafe | B32: Johar Town | C32: Premium casual / continental | L32: To contact | O32: Stylish continental dining known for pastas and steaks — premium casual fit outside the Gulberg/DHA cluster. | R32: Verify it still fits (priority B), then first contact
A33: FiLLi Cafe | B33: Johar Town (and other Lahore branches) | C33: Cafe / tea chain | L33: To contact | O33: Known for a signature Zafran Chai and a strong local following — large audience, worth checking whether the printed menu is text-only. | R33: Verify it still fits (priority B), then first contact
A34: Howdy | B34: Johar Town | C34: Steakhouse / premium casual | L34: To contact | O34: Described as a premium, cowboy-themed steakhouse for burgers and steaks — verify it is not primarily a fast-food/burger operation before pitching. | R34: Verify it still fits (priority C), then first contact
A35: Ranchers | B35: Johar Town | C35: Steakhouse / grill | L35: To contact | O35: Described as a meat-lovers spot for grilled steaks in a rustic setting. | R35: Verify it still fits (priority C), then first contact
A36: Double Shot Coffee | B36: DHA Phase 6 | C36: Cafe / coffee | L36: To contact | O36: Coffee-forward modern cafe in the DHA Phase 6 cluster — good for a single-afternoon walk with other DHA prospects. | R36: Verify it still fits (priority C), then first contact
A37: Kickstart Cafe | B37: DHA Phase 6 | C37: Cafe | L37: To contact | O37: Positively reviewed neighbourhood cafe in the DHA Phase 6 cluster. | R37: Verify it still fits (priority C), then first contact
A38: Chai Hujra | B38: DHA Phase 5 | C38: Cafe / evening venue | L38: To contact | O38: Nightly live-music tea venue in DHA Phase 5 — verify it has a plated food menu (not just tea/snacks) before treating as an AR-menu fit. | R38: Verify it still fits (priority C), then first contact
A39: Kudo's Caff | B39: Johar Town | C39: Cafe | L39: To contact | O39: Trendy neighbourhood cafe for casual meetups and coffee. | R39: Verify it still fits (priority C), then first contact
A40: Buqayvia Restaurant | B40: Johar Town | C40: Casual dining / Pakistani-continental | L40: To contact | O40: Family-casual Pakistani/continental spot — screen for table service and a hero dish before pitching. | R40: Verify it still fits (priority C), then first contact
...

Sheet Influencers
A1: Handle | B1: Tier (nano / micro / macro) | C1: Followers (as checked) | D1: Date checked | E1: Source of the count | F1: Invited on | G1: Reply | H1: Visit date | I1: Post link | J1: Reach of their post | K1: Profile visits to MENVA that week | L1: Notes
A2: EXAMPLE: @handle | B2: micro | C2: 25000 | D2: 46296 | E2: Instagram profile, checked by hand | F2: 46303 | G2: Yes | H2: 46313 | L2: Verify the count before inviting

Sheet Campaigns
A1: Campaign | B1: Idea | C1: Main KPI | D1: Kill criterion (copy from campaigns.md) | E1: Start week | F1: Status | G1: Result so far | H1: Decision
A2: Sight test | B2: Guess the portion from the menu line, then see it at true size | C2: Sends per 1k reach, comments
A3: Dish drop | B3: One real scan revealed each week, "this week on the table" | C3: Saves and comments per post
A4: Menu photos lie | B4: Expectation vs reality, done honestly with real scans only | C4: Sends per 1k reach
A5: Founding tables | B5: The first Lahore restaurants to put their menu on the table (B2B) | C5: "PILOT" DMs
A6: First reactions | B6: Real, consenting diners seeing their dish land in AR | C6: Sends per 1k reach
A7: No replay needed | B7: A pre-approved cricket morning-after card | C7: Reach, sends
